Workbook

Sheet spain_clean
A1: Number | B1: Name | C1: Position | D1: Date of Birth | E1: Age | F1: Nationality | G1: Birth Country | H1: Place of Birth | I1: Height | J1: Market Value | K1: Main Position | L1: Other Positions | M1: Nationality 1 | N1: Nationality 2 | O1: Nationality 3 | P1: Position 2 | Q1: Position 3 | R1: Region
A2: 1.0 | B2: Biel Ribas | C2: Goalkeeper | D2: Dec 2, 1985 | E2: 38 | F2: Spain | G2: Spain | H2: Palma de Mallorca | J2: 1.86 | M2: Spain | R2: =IFERROR(VLOOKUP(spain_clean[[#This Row],[Place of Birth]],region!A:B,2,FALSE),"") -> Comunidad Autónoma de las Islas Baleares
A3: 13.0 | B3: Roberto Santamaría | C3: Goalkeeper | D3: Feb 27, 1985 | E3: 39 | F3: Spain | G3: Spain | H3: Pamplona | J3: 1.83 | M3: Spain | R3: =IFERROR(VLOOKUP(spain_clean[[#This Row],[Place of Birth]],region!A:B,2,FALSE),"") -> Comunidad Foral de Navarra
B4: Miguel Ángel Ávila | C4: Goalkeeper | D4: Apr 18, 1985 | E4: 39 | F4: Spain | G4: Spain | H4: Torremolinos | J4: 1.82 | M4: Spain | R4: =IFERROR(VLOOKUP(spain_clean[[#This Row],[Place of Birth]],region!A:B,2,FALSE),"") -> Comunidad Autónoma de Andalucía
B5: Francisco Javier Rosales Simón | C5: Goalkeeper | D5: Dec 9, 1985 | E5: 38 | F5: Spain | G5: Spain | H5: La Linea de la Conceocion | J5: 1.8 | M5: Spain | R5: =IFERROR(VLOOKUP(spain_clean[[#This Row],[Place of Birth]],region!A:B,2,FALSE),"")
B6: Francisco Asta | C6: Goalkeeper | D6: Nov 4, 1985 | E6: 38 | F6: Spain | G6: Spain | H6: Almeria | J6: 1.83 | M6: Spain | R6: =IFERROR(VLOOKUP(spain_clean[[#This Row],[Place of Birth]],region!A:B,2,FALSE),"") -> Comunidad Autónoma de Andalucía
B7: Marcos Contreras | C7: Goalkeeper | D7: Aug 16, 1985 | E7: 38 | F7: Spain | G7: Spain | H7: Sevilla | J7: 1.83 | M7: Spain | R7: =IFERROR(VLOOKUP(spain_clean[[#This Row],[Place of Birth]],region!A:B,2,FALSE),"") -> Comunidad Autónoma de Andalucía
B8: Miguel Ángel Trenado | C8: Goalkeeper | D8: Jun 9, 1985 | E8: 39 | F8: Spain | G8: Spain | H8: Madrid | J8: 1.85 | M8: Spain | R8: =IFERROR(VLOOKUP(spain_clean[[#This Row],[Place of Birth]],region!A:B,2,FALSE),"") -> Comunidad de Madrid
B9: Guillermo Ubierna | C9: Goalkeeper | D9: Feb 27, 1985 | E9: 39 | F9: Spain | G9: Spain | H9: Alcobendas | J9: 1.9 | M9: Spain | R9: =IFERROR(VLOOKUP(spain_clean[[#This Row],[Place of Birth]],region!A:B,2,FALSE),"") -> Comunidad de Madrid
B10: Pablo Gómez | C10: Goalkeeper | D10: Sep 20, 1985 | E10: 38 | F10: Spain | G10: Spain | H10: Potes | J10: 1.83 | M10: Spain | R10: =IFERROR(VLOOKUP(spain_clean[[#This Row],[Place of Birth]],region!A:B,2,FALSE),"") -> Comunidad Autónoma de Cantabria
B11: Roberto Cirauqui | C11: Goalkeeper | D11: May 15, 1985 | E11: 39 | F11: Spain | G11: Spain | H11: Funes | J11: 1.86 | M11: Spain | R11: =IFERROR(VLOOKUP(spain_clean[[#This Row],[Place of Birth]],region!A:B,2,FALSE),"") -> Comunidad Foral de Navarra
B12: Dani Castro | C12: Goalkeeper | D12: Sep 24, 1985 | E12: 38 | F12: Spain | G12: Spain | H12: Gijon | J12: 1.88 | M12: Spain | R12: =IFERROR(VLOOKUP(spain_clean[[#This Row],[Place of Birth]],region!A:B,2,FALSE),"") -> Comunidad Autónoma del Principado de Asturias
B13: Raúl Sáez | C13: Goalkeeper | D13: Aug 20, 1985 | E13: 38 | F13: Spain | G13: Spain | H13: La Pobla de Mafumet | M13: Spain | R13: =IFERROR(VLOOKUP(spain_clean[[#This Row],[Place of Birth]],region!A:B,2,FALSE),"") -> Catalunya
B14: Jon Juanes | C14: Goalkeeper | D14: Jan 16, 1985 | E14: 39 | F14: Spain | G14: Spain | H14: Barakaldo | J14: 1.87 | M14: Spain | R14: =IFERROR(VLOOKUP(spain_clean[[#This Row],[Place of Birth]],region!A:B,2,FALSE),"") -> Euskal Autonomia Erkidegoa
A15: 13.0 | B15: Francisco Dorronsoro | C15: Goalkeeper | D15: May 22, 1985 | E15: 39 | F15: Spain | G15: Spain | H15: Torrelavega | J15: 1.8 | M15: Spain | R15: =IFERROR(VLOOKUP(spain_clean[[#This Row],[Place of Birth]],region!A:B,2,FALSE),"") -> Comunidad Autónoma de Cantabria
A16: 1.0 | B16: Jonay Quintana | C16: Goalkeeper | D16: Nov 27, 1985 | E16: 38 | F16: Spain | G16: Spain | H16: Las Palmas de Gran Canaria | M16: Spain | R16: =IFERROR(VLOOKUP(spain_clean[[#This Row],[Place of Birth]],region!A:B,2,FALSE),"") -> Comunidad Autónoma de Canarias
B17: David Larumbe | C17: Goalkeeper | D17: Jan 31, 1985 | E17: 39 | F17: Spain | G17: Spain | H17: Pamplona | M17: Spain | R17: =IFERROR(VLOOKUP(spain_clean[[#This Row],[Place of Birth]],region!A:B,2,FALSE),"") -> Comunidad Foral de Navarra
B18: Imanol Pérez | C18: Goalkeeper | D18: Jun 1, 1985 | E18: 39 | F18: Spain | G18: Spain | H18: Errenteria | J18: 1.85 | M18: Spain | R18: =IFERROR(VLOOKUP(spain_clean[[#This Row],[Place of Birth]],region!A:B,2,FALSE),"") -> Euskal Autonomia Erkidegoa
B19: Chato | C19: Goalkeeper | D19: Jan 4, 1985 | E19: 39 | F19: Spain | G19: Spain | H19: Tomelloso | M19: Spain | R19: =IFERROR(VLOOKUP(spain_clean[[#This Row],[Place of Birth]],region!A:B,2,FALSE),"") -> Comunidad Autónoma de Castilla-La Mancha
A20: 1.0 | B20: Manolo Delgado | C20: Goalkeeper | D20: May 21, 1985 | E20: 39 | F20: Spain | G20: Spain | H20: Manzanares | J20: 1.85 | M20: Spain | R20: =IFERROR(VLOOKUP(spain_clean[[#This Row],[Place of Birth]],region!A:B,2,FALSE),"") -> Comunidad Autónoma de Castilla-La Mancha
B21: Josué Castells | C21: Goalkeeper | D21: Jan 9, 1985 | E21: 39 | F21: Peru, Spain | G21: Spain | H21: Barcelona | M21: Peru | N21: Spain | R21: =IFERROR(VLOOKUP(spain_clean[[#This Row],[Place of Birth]],region!A:B,2,FALSE),"") -> Catalunya
B22: Chele | C22: Goalkeeper | D22: Mar 26, 1985 | E22: 39 | F22: Spain | G22: Spain | H22: Madrid | J22: 1.8 | M22: Spain | R22: =IFERROR(VLOOKUP(spain_clean[[#This Row],[Place of Birth]],region!A:B,2,FALSE),"") -> Comunidad de Madrid
B23: Roberto Román | C23: Goalkeeper | D23: Jul 4, 1985 | E23: 39 | F23: Spain | G23: Spain | H23: Caceres | J23: 1.89 | M23: Spain | R23: =IFERROR(VLOOKUP(spain_clean[[#This Row],[Place of Birth]],region!A:B,2,FALSE),"") -> Comunidad Autónoma de Extremadura
B24: Carlos Saavedra | C24: Goalkeeper | D24: May 3, 1985 | E24: 39 | F24: Spain | G24: Spain | H24: Madrid | J24: 1.87 | M24: Spain | R24: =IFERROR(VLOOKUP(spain_clean[[#This Row],[Place of Birth]],region!A:B,2,FALSE),"") -> Comunidad de Madrid
B25: Oier San Miguel | C25: Goalkeeper | D25: Jan 20, 1985 | E25: 39 | F25: Spain | G25: Spain | H25: Ondarroa | J25: 1.87 | M25: Spain | R25: =IFERROR(VLOOKUP(spain_clean[[#This Row],[Place of Birth]],region!A:B,2,FALSE),"") -> Euskal Autonomia Erkidegoa
B26: David Alemán | C26: Goalkeeper | D26: Feb 7, 1985 | E26: 39 | F26: Spain | G26: Spain | H26: Pajara | J26: 1.74 | M26: Spain | R26: =IFERROR(VLOOKUP(spain_clean[[#This Row],[Place of Birth]],region!A:B,2,FALSE),"") -> Comunidad Autónoma de Canarias
A27: 13.0 | B27: Nauzet Pérez | C27: Goalkeeper | D27: Mar 1, 1985 | E27: 39 | F27: Spain | G27: Portugal | H27: Las Palmas de Gran Canaria | J27: 1.9 | M27: Spain | R27: =IFERROR(VLOOKUP(spain_clean[[#This Row],[Place of Birth]],region!A:B,2,FALSE),"") -> Comunidad Autónoma de Canarias
B28: José Manuel Camacho | C28: Goalkeeper | D28: Jul 9, 1985 | E28: 39 | F28: Spain | G28: Portugal | H28: Jerez de la Frontera | J28: 1.82 | M28: Spain | R28: =IFERROR(VLOOKUP(spain_clean[[#This Row],[Place of Birth]],region!A:B,2,FALSE),"") -> Comunidad Autónoma de Andalucía
B29: Ariza | C29: Goalkeeper | D29: Apr 1, 1985 | E29: 39 | F29: Spain | G29: Portugal | H29: Malaga | J29: 1.82 | M29: Spain | R29: =IFERROR(VLOOKUP(spain_clean[[#This Row],[Place of Birth]],region!A:B,2,FALSE),"") -> Comunidad Autónoma de Andalucía
B30: Juan Manuel Torrente | C30: Goalkeeper | D30: Jun 1, 1985 | E30: 39 | F30: Spain | G30: Portugal | H30: Puerto Lumbreras | J30: 1.85 | M30: Spain | R30: =IFERROR(VLOOKUP(spain_clean[[#This Row],[Place of Birth]],region!A:B,2,FALSE),"") -> Comunidad Autónoma de la Región de Murcia
B31: Alberto García | C31: Goalkeeper | D31: Feb 9, 1985 | E31: 39 | F31: Spain | G31: Portugal | H31: Barcelona | J31: 1.82 | M31: Spain | R31: =IFERROR(VLOOKUP(spain_clean[[#This Row],[Place of Birth]],region!A:B,2,FALSE),"") -> Catalunya
B32: David Montero | C32: Goalkeeper | D32: Mar 12, 1985 | E32: 39 | F32: Spain | G32: Portugal | H32: Salamanca | J32: 1.81 | M32: Spain | R32: =IFERROR(VLOOKUP(spain_clean[[#This Row],[Place of Birth]],region!A:B,2,FALSE),"") -> Comunidad Autónoma de Castilla y León
B33: Aitor Alcalde | C33: Goalkeeper | D33: May 22, 1985 | E33: 39 | F33: Spain | G33: Portugal | H33: Erandio | J33: 1.86 | M33: Spain | R33: =IFERROR(VLOOKUP(spain_clean[[#This Row],[Place of Birth]],region!A:B,2,FALSE),"") -> Euskal Autonomia Erkidegoa
B34: Alberto Montero | C34: Goalkeeper | D34: Mar 28, 1985 | E34: 39 | F34: Spain | G34: Portugal | H34: Barcelona | J34: 1.86 | M34: Spain | R34: =IFERROR(VLOOKUP(spain_clean[[#This Row],[Place of Birth]],region!A:B,2,FALSE),"") -> Catalunya
B35: Sergio López | C35: Goalkeeper | D35: Oct 29, 1985 | E35: 38 | F35: Spain | G35: Portugal | H35: Santander | J35: 1.85 | M35: Spain | R35: =IFERROR(VLOOKUP(spain_clean[[#This Row],[Place of Birth]],region!A:B,2,FALSE),"") -> Comunidad Autónoma de Cantabria
B36: Manel Arroyo | C36: Goalkeeper | D36: Feb 21, 1985 | E36: 39 | F36: Spain | G36: Portugal | H36: Madrid | J36: 1.86 | M36: Spain | R36: =IFERROR(VLOOKUP(spain_clean[[#This Row],[Place of Birth]],region!A:B,2,FALSE),"") -> Comunidad de Madrid
B37: Jorge Larrosa | C37: Goalkeeper | D37: Dec 16, 1985 | E37: 38 | F37: Spain | G37: Portugal | H37: Huesca | J37: 1.81 | M37: Spain | R37: =IFERROR(VLOOKUP(spain_clean[[#This Row],[Place of Birth]],region!A:B,2,FALSE),"") -> Comunidad Autónoma de Aragón
B38: Darío Fernández | C38: Goalkeeper | D38: Jun 16, 1985 | E38: 39 | F38: Spain | G38: Portugal | H38: Granada | J38: 1.82 | M38: Spain | R38: =IFERROR(VLOOKUP(spain_clean[[#This Row],[Place of Birth]],region!A:B,2,FALSE),"") -> Comunidad Autónoma de Andalucía
B39: Dani | C39: Goalkeeper | D39: Apr 23, 1985 | E39: 39 | F39: Spain | G39: Portugal | H39: Cadiz | J39: 1.8 | M39: Spain | R39: =IFERROR(VLOOKUP(spain_clean[[#This Row],[Place of Birth]],region!A:B,2,FALSE),"") -> Comunidad Autónoma de Andalucía
... B41: Manolo Reina | C41: Goalkeeper | D41: Apr 1, 1985 | E41: 39 | F41: Spain | G41: Portugal | H41: Villanueva del Trabuco | J41: 1.86 | M41: Spain | R41: =IFERROR(VLOOKUP(spain_clean[[#This Row],[Place of Birth]],region!A:B,2,FALSE),"") -> Comunidad Autónoma de Andalucía
...

Sheet region
A1: asciiname | B1: region
A2: Kingdom of Spain
A3: Andalusia | B3: Comunidad Autónoma de Andalucía
A4: Catalunya | B4: Catalunya
A5: Comunidad de Madrid | B5: Comunidad de Madrid
A6: Provincia de Madrid | B6: Comunidad de Madrid
A7: Provincia de Barcelona | B7: Catalunya
A8: Comunitat Valenciana | B8: Comunidad Valenciana
A9: Madrid | B9: Comunidad de Madrid
A10: Madrid | B10: Comunidad de Madrid
A11: Galicia | B11: Comunidad Autónoma de Galicia
A12: Provincia de Valencia | B12: Comunidad Valenciana
A13: Castilla y Leon | B13: Comunidad Autónoma de Castilla y León
A14: Euskal Autonomia Erkidegoa | B14: Euskal Autonomia Erkidegoa
... A16322: Claramunt | B16322: Catalunya

Sheet TCD
A1: Nationality 2 | B1: (Plusieurs éléments)
A3: Étiquettes de lignes | B3: Nombre de Name
A4: Albania | B4: 1
A5: Algeria | B5: 2
A6: Andorra | B6: 6
A7: Angola | B7: 1
A8: Argentina | B8: 13
A9: Armenia | B9: 1
A10: Australia | B10: 2
A11: Azerbaijan | B11: 1
A12: Belarus | B12: 1
A13: Belgium | B13: 4
A14: Bolivia | B14: 5
A15: Bosnia-Herzegovina | B15: 1
... A86: Total général | B86: 813
