Workbook

Sheet france_clean
A1: Number | B1: Name | C1: Position | D1: Date of Birth | E1: Age | F1: Nationality | G1: Birth Country | H1: Place of Birth | I1: Height | J1: Market Value | K1: Other Positions | L1: Nationality 1 | M1: Nationality 2 | N1: Position 2 | O1: Position 3 | P1: Region | Q1: Département | R1: Continent
A2: 16 | B2: Jean-Louis Leca | C2: Goalkeeper | D2: Sep 21, 1985 | E2: 38 | F2: France | G2: France | H2: Bastia | I2: 1.8 | J2: €200k | L2: France | P2: Corse | Q2: Haute-Corse | R2: =IFERROR(VLOOKUP(france_clean[[#This Row],[Nationality 1]],continent!A:B,2,FALSE),"") -> France
B3: Mathieu Suffissais | C3: Goalkeeper | D3: May 30, 1985 | E3: 38 | F3: France | G3: France | H3: Laval | I3: 1.83 | J3: - | L3: France | P3: Pays de la Loire | Q3: Mayenne | R3: =IFERROR(VLOOKUP(france_clean[[#This Row],[Nationality 1]],continent!A:B,2,FALSE),"") -> France
B4: Gérald Delaporte | C4: Goalkeeper | D4: Dec 18, 1985 | E4: 38 | F4: France | G4: France | J4: - | L4: France | R4: =IFERROR(VLOOKUP(france_clean[[#This Row],[Nationality 1]],continent!A:B,2,FALSE),"") -> France
B5: Thomas Fedrigo | C5: Goalkeeper | D5: May 10, 1985 | E5: 38 | F5: France, Italy | G5: France | H5: Paray-le-Monial | I5: 1.8 | J5: - | L5: France | M5: Italy | P5: Bourgogne-Franche-Comté | Q5: Saône-et-Loire | R5: =IFERROR(VLOOKUP(france_clean[[#This Row],[Nationality 1]],continent!A:B,2,FALSE),"") -> France
B6: Florian Piolot | C6: Goalkeeper | D6: Dec 24, 1985 | E6: 38 | F6: France | G6: France | H6: Pabu | I6: 1.86 | J6: - | L6: France | P6: Bretagne | Q6: Côtes-d'Armor | R6: =IFERROR(VLOOKUP(france_clean[[#This Row],[Nationality 1]],continent!A:B,2,FALSE),"") -> France
B7: Sébastien Callamand | C7: Goalkeeper | D7: Jun 26, 1985 | E7: 38 | F7: France | G7: France | H7: Oyonnax | I7: 1.86 | J7: - | L7: France | P7: Auvergne-Rhône-Alpes | Q7: Ain | R7: =IFERROR(VLOOKUP(france_clean[[#This Row],[Nationality 1]],continent!A:B,2,FALSE),"") -> France
B8: Foued Baba Alla | C8: Goalkeeper | D8: Sep 23, 1985 | E8: 38 | F8: Morocco, France | G8: France | H8: Graulhet | J8: - | L8: Morocco | M8: France | P8: Occitanie | Q8: Tarn | R8: =IFERROR(VLOOKUP(france_clean[[#This Row],[Nationality 1]],continent!A:B,2,FALSE),"") -> Africa
B9: Hadama Bathily | C9: Goalkeeper | D9: Jun 18, 1985 | E9: 38 | F9: France, Mali | G9: France | H9: Rouen | I9: 1.85 | J9: - | L9: France | M9: Mali | P9: Normandie | Q9: Seine-Maritime | R9: =IFERROR(VLOOKUP(france_clean[[#This Row],[Nationality 1]],continent!A:B,2,FALSE),"") -> France
B10: Florian Aït Ali | C10: Goalkeeper | D10: Jan 4, 1985 | E10: 39 | F10: France | G10: France | H10: Toulouse | I10: 1.76 | J10: - | L10: France | P10: Occitanie | Q10: Haute-Garonne | R10: =IFERROR(VLOOKUP(france_clean[[#This Row],[Nationality 1]],continent!A:B,2,FALSE),"") -> France
B11: Thomas Aupic | C11: Goalkeeper | D11: Feb 24, 1985 | E11: 39 | F11: France | G11: France | H11: Dijon | I11: 1.77 | J11: - | L11: France | P11: Bourgogne-Franche-Comté | Q11: Côte-d'Or | R11: =IFERROR(VLOOKUP(france_clean[[#This Row],[Nationality 1]],continent!A:B,2,FALSE),"") -> France
B12: Arnaud Ribeiro | C12: Goalkeeper | D12: Jun 6, 1985 | E12: 38 | F12: France | G12: France | H12: Lagny-sur-Marne | I12: 1.86 | J12: - | L12: France | P12: Île-de-France | Q12: Seine-et-Marne | R12: =IFERROR(VLOOKUP(france_clean[[#This Row],[Nationality 1]],continent!A:B,2,FALSE),"") -> France
B13: Gregory Douard | C13: Goalkeeper | D13: Aug 1, 1985 | E13: 38 | F13: France | G13: France | H13: Chateaubriant | I13: 1.8 | J13: - | L13: France | R13: =IFERROR(VLOOKUP(france_clean[[#This Row],[Nationality 1]],continent!A:B,2,FALSE),"") -> France
B14: Christopher Pilar | C14: Goalkeeper | D14: Mar 29, 1985 | E14: 38 | F14: Portugal, France | G14: France | H14: Dijon | I14: 1.85 | J14: - | L14: Portugal | M14: France | P14: Bourgogne-Franche-Comté | Q14: Côte-d'Or | R14: =IFERROR(VLOOKUP(france_clean[[#This Row],[Nationality 1]],continent!A:B,2,FALSE),"") -> Europe
B15: Sébastien Jaffré | C15: Goalkeeper | D15: Jan 26, 1985 | E15: 39 | F15: France | G15: France | H15: Morlaix | J15: - | L15: France | P15: Bretagne | Q15: Finistère | R15: =IFERROR(VLOOKUP(france_clean[[#This Row],[Nationality 1]],continent!A:B,2,FALSE),"") -> France
B16: Arnaud Maillot | C16: Goalkeeper | D16: Mar 12, 1985 | E16: 38 | F16: France | G16: France | H16: Besancon | I16: 1.78 | J16: - | L16: France | P16: Bourgogne-Franche-Comté | Q16: Doubs | R16: =IFERROR(VLOOKUP(france_clean[[#This Row],[Nationality 1]],continent!A:B,2,FALSE),"") -> France
B17: Benjamin Rytlewski | C17: Goalkeeper | D17: Dec 26, 1985 | E17: 38 | F17: France, Poland | G17: France | H17: Bethune | I17: 1.86 | J17: - | L17: France | M17: Poland | P17: Hauts-de-France | Q17: Pas-de-Calais | R17: =IFERROR(VLOOKUP(france_clean[[#This Row],[Nationality 1]],continent!A:B,2,FALSE),"") -> France
A18: 30 | B18: Stéphane Schneider | C18: Goalkeeper | D18: Jan 3, 1985 | E18: 39 | F18: France | G18: France | H18: Strasbourg | I18: 1.87 | J18: - | L18: France | P18: Grand Est | Q18: Bas-Rhin | R18: =IFERROR(VLOOKUP(france_clean[[#This Row],[Nationality 1]],continent!A:B,2,FALSE),"") -> France
B19: Guillaume Garnier | C19: Goalkeeper | D19: Jul 5, 1985 | E19: 38 | F19: France | G19: France | H19: Mantes-la-Jolie | J19: - | L19: France | P19: Île-de-France | Q19: Yvelines | R19: =IFERROR(VLOOKUP(france_clean[[#This Row],[Nationality 1]],continent!A:B,2,FALSE),"") -> France
B20: Nicolas D'Alessio | C20: Goalkeeper | D20: Dec 24, 1985 | E20: 38 | F20: France | G20: France | I20: 1.84 | J20: - | L20: France | R20: =IFERROR(VLOOKUP(france_clean[[#This Row],[Nationality 1]],continent!A:B,2,FALSE),"") -> France
B21: Lucas Rastello | C21: Goalkeeper | D21: Apr 21, 1985 | E21: 38 | F21: France | G21: France | H21: Marseille | I21: 1.79 | J21: - | L21: France | P21: Provence-Alpes-Côte d'Azur | Q21: Bouches-du-Rhône | R21: =IFERROR(VLOOKUP(france_clean[[#This Row],[Nationality 1]],continent!A:B,2,FALSE),"") -> France
B22: Cédric Si Mohammed | C22: Goalkeeper | D22: Jan 9, 1985 | E22: 39 | F22: Algeria, France | G22: France | H22: Roanne | I22: 1.83 | J22: - | L22: Algeria | M22: France | P22: Auvergne-Rhône-Alpes | Q22: Loire | R22: =IFERROR(VLOOKUP(france_clean[[#This Row],[Nationality 1]],continent!A:B,2,FALSE),"") -> Africa
B23: Clément Maury | C23: Goalkeeper | D23: Nov 20, 1985 | E23: 38 | F23: France | G23: France | H23: Aurillac | I23: 1.82 | J23: - | L23: France | P23: Auvergne-Rhône-Alpes | Q23: Cantal | R23: =IFERROR(VLOOKUP(france_clean[[#This Row],[Nationality 1]],continent!A:B,2,FALSE),"") -> France
B24: Yann Hubert | C24: Goalkeeper | D24: Jan 9, 1985 | E24: 39 | F24: France | G24: France | H24: Nimes | I24: 1.86 | J24: - | L24: France | P24: Occitanie | Q24: Gard | R24: =IFERROR(VLOOKUP(france_clean[[#This Row],[Nationality 1]],continent!A:B,2,FALSE),"") -> France
B25: Adrien Gato | C25: Goalkeeper | D25: Dec 16, 1985 | E25: 38 | F25: France | G25: France | H25: Neuilly-sur-Seine | I25: 1.74 | J25: - | L25: France | P25: Île-de-France | Q25: Hauts-de-Seine | R25: =IFERROR(VLOOKUP(france_clean[[#This Row],[Nationality 1]],continent!A:B,2,FALSE),"") -> France
B26: Gaëtan Deneuve | C26: Goalkeeper | D26: May 3, 1985 | E26: 38 | F26: France | G26: France | H26: Harfleur | I26: 1.83 | J26: - | L26: France | P26: Normandie | Q26: Seine-Maritime | R26: =IFERROR(VLOOKUP(france_clean[[#This Row],[Nationality 1]],continent!A:B,2,FALSE),"") -> France
B27: Mickael Castejon | C27: Goalkeeper | D27: Mar 21, 1985 | E27: 38 | F27: France, Spain | G27: France | H27: Libourne | I27: 1.81 | J27: - | L27: France | M27: Spain | P27: Nouvelle-Aquitaine | Q27: Gironde | R27: =IFERROR(VLOOKUP(france_clean[[#This Row],[Nationality 1]],continent!A:B,2,FALSE),"") -> France
B28: Fabien Farnolle | C28: Goalkeeper | D28: Feb 5, 1985 | E28: 39 | F28: Benin, France | G28: France | H28: Bordeaux | I28: 1.97 | J28: - | L28: Benin | M28: France | P28: Nouvelle-Aquitaine | Q28: Gironde | R28: =IFERROR(VLOOKUP(france_clean[[#This Row],[Nationality 1]],continent!A:B,2,FALSE),"") -> Africa
B29: Simon Pouplin | C29: Goalkeeper | D29: May 28, 1985 | E29: 38 | F29: France | G29: France | H29: Cholet | J29: - | L29: France | P29: Pays de la Loire | Q29: Maine-et-Loire | R29: =IFERROR(VLOOKUP(france_clean[[#This Row],[Nationality 1]],continent!A:B,2,FALSE),"") -> France
B30: Benoît Benvegnu | C30: Goalkeeper | D30: Jan 18, 1985 | E30: 39 | F30: France | G30: France | H30: Montauban | I30: 1.84 | J30: - | L30: France | P30: Occitanie | Q30: Tarn-et-Garonne | R30: =IFERROR(VLOOKUP(france_clean[[#This Row],[Nationality 1]],continent!A:B,2,FALSE),"") -> France
A31: 22 | B31: Alexandre Martinovic | C31: Goalkeeper | D31: May 31, 1985 | E31: 38 | F31: France, Montenegro | G31: France | H31: Montbeliard | I31: 1.93 | J31: - | L31: France | M31: Montenegro | P31: Bourgogne-Franche-Comté | Q31: Doubs | R31: =IFERROR(VLOOKUP(france_clean[[#This Row],[Nationality 1]],continent!A:B,2,FALSE),"") -> France
B32: Johan Lapeyre | C32: Goalkeeper | D32: Aug 3, 1985 | E32: 38 | F32: France | G32: France | H32: Le Plessis-Bouchard | I32: 1.78 | J32: - | L32: France | P32: Île-de-France | Q32: Val-d'Oise | R32: =IFERROR(VLOOKUP(france_clean[[#This Row],[Nationality 1]],continent!A:B,2,FALSE),"") -> France
B33: Nicolas Cousin | C33: Goalkeeper | D33: Jul 11, 1985 | E33: 38 | F33: France | G33: France | H33: Nemours | I33: 1.84 | J33: - | L33: France | P33: Île-de-France | Q33: Seine-et-Marne | R33: =IFERROR(VLOOKUP(france_clean[[#This Row],[Nationality 1]],continent!A:B,2,FALSE),"") -> France
B34: Alexis Thébaux | C34: Goalkeeper | D34: Mar 17, 1985 | E34: 38 | F34: France | G34: France | H34: Les Sables-d'Olonne | I34: 1.85 | J34: - | L34: France | P34: Pays de la Loire | Q34: Vendée | R34: =IFERROR(VLOOKUP(france_clean[[#This Row],[Nationality 1]],continent!A:B,2,FALSE),"") -> France
A35: 24 | B35: Yohann Lacroix | C35: Goalkeeper | D35: Feb 1, 1985 | E35: 39 | F35: France | G35: France | H35: Thonon-les-Bains | I35: 1.94 | J35: - | L35: France | P35: Auvergne-Rhône-Alpes | Q35: Haute-Savoie | R35: =IFERROR(VLOOKUP(france_clean[[#This Row],[Nationality 1]],continent!A:B,2,FALSE),"") -> France
B36: Wilfried Bulgare | C36: Goalkeeper | D36: Feb 26, 1985 | E36: 39 | F36: Martinique, France | G36: France | H36: Toulon | I36: 1.78 | J36: - | L36: Martinique | M36: France | P36: Provence-Alpes-Côte d'Azur | Q36: Var | R36: =IFERROR(VLOOKUP(france_clean[[#This Row],[Nationality 1]],continent!A:B,2,FALSE),"") -> North America
A37: 1 | B37: Hugo Lloris | C37: Goalkeeper | D37: Dec 26, 1986 | E37: 37 | F37: France | G37: France | H37: Nice | I37: 1.88 | J37: €1.50m | L37: France | P37: Provence-Alpes-Côte d'Azur | Q37: Alpes-Maritimes | R37: =IFERROR(VLOOKUP(france_clean[[#This Row],[Nationality 1]],continent!A:B,2,FALSE),"") -> France
A38: 23 | B38: Raïs M'Bolhi | C38: Goalkeeper | D38: Apr 25, 1986 | E38: 37 | F38: Algeria, France | G38: France | H38: Paris | I38: 1.9 | J38: €200k | L38: Algeria | M38: France | P38: Île-de-France | Q38: Paris | R38: =IFERROR(VLOOKUP(france_clean[[#This Row],[Nationality 1]],continent!A:B,2,FALSE),"") -> Africa
B39: Jérôme Mançon | C39: Goalkeeper | D39: Jan 10, 1986 | E39: 38 | F39: France | G39: France | H39: Marcq-en-Baroeul | I39: 1.77 | J39: - | L39: France | R39: =IFERROR(VLOOKUP(france_clean[[#This Row],[Nationality 1]],continent!A:B,2,FALSE),"") -> France
B40: Julien Fondraz | C40: Goalkeeper | D40: Jun 25, 1986 | E40: 37 | F40: France | G40: France | H40: Coutances | J40: - | L40: France | P40: Normandie | Q40: Manche | R40: =IFERROR(VLOOKUP(france_clean[[#This Row],[Nationality 1]],continent!A:B,2,FALSE),"") -> France
...

Sheet continent
A1: country | B1: continent
A2: Afghanistan | B2: Asia
A3: Albania | B3: Europe
A4: Algeria | B4: Africa
A5: American Samoa | B5: Oceania
A6: Andorra | B6: Europe
A7: Angola | B7: Africa
A8: Anguilla | B8: North America
A9: Antigua and Barbuda | B9: North America
A10: Argentina | B10: South America
A11: Armenia | B11: Asia
A12: Aruba | B12: North America
... A241: Wales | B241: Europe
A242: Macau
A243: The Gambia | B243: Africa
A244: Neukaledonien | B244: Oceania
A245: Réunion | B245: Africa

Sheet France_regions_departments
A1: name | B1: Région | C1: Département
A2: L'Abergement-Clemenciat | B2: Auvergne-Rhône-Alpes | C2: Ain
A3: L'Abergement-de-Varey | B3: Auvergne-Rhône-Alpes | C3: Ain
A4: Amberieu-en-Bugey | B4: Auvergne-Rhône-Alpes | C4: Ain
A5: Amberieux-en-Dombes | B5: Auvergne-Rhône-Alpes | C5: Ain
A6: Ambleon | B6: Auvergne-Rhône-Alpes | C6: Ain
A7: Ambronay | B7: Auvergne-Rhône-Alpes | C7: Ain
A8: Ambutrix | B8: Auvergne-Rhône-Alpes | C8: Ain
A9: Andert-et-Condon | B9: Auvergne-Rhône-Alpes | C9: Ain
A10: Anglefort | B10: Auvergne-Rhône-Alpes | C10: Ain
A11: Apremont | B11: Auvergne-Rhône-Alpes | C11: Ain
A12: Aranc | B12: Auvergne-Rhône-Alpes | C12: Ain
... A15: Arboys en Bugey | B15: Auvergne-Rhône-Alpes | C15: Ain
A16: Arbignieu
A17: Arbigny | B17: Auvergne-Rhône-Alpes | C17: Ain
A18: Argis | B18: Auvergne-Rhône-Alpes | C18: Ain
A19: Armix | B19: Auvergne-Rhône-Alpes | C19: Ain
A20: Ars-sur-Formans | B20: Auvergne-Rhône-Alpes | C20: Ain
A21: Artemare | B21: Auvergne-Rhône-Alpes | C21: Ain
A22: Asnières-sur-Saône | B22: Auvergne-Rhône-Alpes | C22: Ain
A23: Attignat | B23: Auvergne-Rhône-Alpes | C23: Ain
A24: Bâge-Dommartin | B24: Auvergne-Rhône-Alpes | C24: Ain
A25: Bâge-la-Ville
A26: Bâge-le-Châtel | B26: Auvergne-Rhône-Alpes | C26: Ain
A27: Balan | B27: Auvergne-Rhône-Alpes | C27: Ain
A28: Baneins | B28: Auvergne-Rhône-Alpes | C28: Ain
A29: Beaupont | B29: Auvergne-Rhône-Alpes | C29: Ain
A30: Beauregard | B30: Auvergne-Rhône-Alpes | C30: Ain
A31: Bellignat | B31: Auvergne-Rhône-Alpes | C31: Ain
A32: Beligneux | B32: Auvergne-Rhône-Alpes | C32: Ain
A33: Valserhône | B33: Auvergne-Rhône-Alpes | C33: Ain
A34: Bellegarde-sur-Valserine
A35: Belley | B35: Auvergne-Rhône-Alpes | C35: Ain
A36: Belleydoux | B36: Auvergne-Rhône-Alpes | C36: Ain
A37: Valromey-sur-Seran | B37: Auvergne-Rhône-Alpes | C37: Ain
A38: Belmont-Luthezieu
A39: Benonces | B39: Auvergne-Rhône-Alpes | C39: Ain
A40: Beny | B40: Auvergne-Rhône-Alpes | C40: Ain
A41: Beon
A42: Bereziat | B42: Auvergne-Rhône-Alpes | C42: Ain
...

Sheet TCD
A1: Region | B1: Île-de-France
A2: Nationality 1 | B2: (Tous)
A3: Nationality 2 | B3: (Tous)
A5: Étiquettes de lignes | B5: Nombre de Name
A6: France | B6: 1570 | E6: 1570 | F6: =E6/GETPIVOTDATA("Name",$A$5) -> 0.73605251 | I6: 6647 | J6: =I6/GETPIVOTDATA("Name",$A$5) -> 3.1162682
A7: Africa | B7: 377 | E7: 356 | F7: =E7/GETPIVOTDATA("Name",$A$5) -> 0.16690108 | I7: 1113 | J7: =I7/GETPIVOTDATA("Name",$A$5) -> 0.52180028
A8: North America | B8: 91 | E8: 91 | F8: =E8/GETPIVOTDATA("Name",$A$5) -> 0.042662916 | I8: 218 | J8: =I8/GETPIVOTDATA("Name",$A$5) -> 0.10220347
A9: Europe | B9: 58 | E9: 57 | F9: =E9/GETPIVOTDATA("Name",$A$5) -> 0.026722925 | I9: 145 | J9: =I9/GETPIVOTDATA("Name",$A$5) -> 0.067979372
A10: Asia | B10: 25 | E10: 14 | F10: =E10/GETPIVOTDATA("Name",$A$5) -> 0.0065635256 | I10: 144 | J10: =I10/GETPIVOTDATA("Name",$A$5) -> 0.067510549
A11: South America | B11: 10 | E11: 10 | F11: =E11/GETPIVOTDATA("Name",$A$5) -> 0.0046882325 | I11: 18 | J11: =I11/GETPIVOTDATA("Name",$A$5) -> 0.0084388186
A12: Oceania | B12: 2 | E12: 2 | F12: =E12/GETPIVOTDATA("Name",$A$5) -> 0.00093764651 | I12: 6 | J12: =I12/GETPIVOTDATA("Name",$A$5) -> 0.0028129395
A13: Total général | B13: 2133
