Workbook

Sheet portugal_clean
A1: Number | B1: Name | C1: Position | D1: Date of Birth | E1: Age | F1: Nationality | G1: Birth Country | H1: Place of Birth | I1: Height | J1: Market Value | K1: Main Position | L1: Other Positions | M1: Nationality 1 | N1: Nationality 2 | O1: Position 2 | P1: Position 3 | Q1: Region
A2: 1.0 | B2: António Filipe | C2: Goalkeeper | D2: 31151 | E2: 38 | F2: Portugal | G2: Portugal | H2: Gondomar | J2: 1.87 | M2: Portugal | Q2: =IFERROR(VLOOKUP(portugal_clean[[#This Row],[Place of Birth]],region!A:B,2,FALSE),"") -> Porto
B3: Carlos Magalhães | C3: Goalkeeper | D3: 31152 | E3: 38 | F3: Portugal | G3: Portugal | H3: Porto | J3: 1.78 | M3: Portugal | Q3: =IFERROR(VLOOKUP(portugal_clean[[#This Row],[Place of Birth]],region!A:B,2,FALSE),"") -> Porto
B4: Manuel Silveira | C4: Goalkeeper | D4: 31195 | E4: 38 | F4: Portugal, Andorra | G4: Portugal | M4: Portugal | N4: Andorra | Q4: =IFERROR(VLOOKUP(portugal_clean[[#This Row],[Place of Birth]],region!A:B,2,FALSE),"")
B5: Tiago Alves | C5: Goalkeeper | D5: 31182 | E5: 38 | F5: Portugal, France | G5: Portugal | H5: Chaves | J5: 1.83 | M5: Portugal | N5: France | Q5: =IFERROR(VLOOKUP(portugal_clean[[#This Row],[Place of Birth]],region!A:B,2,FALSE),"") -> Vila Real
B6: Torcato | C6: Goalkeeper | D6: 31093 | E6: 39 | F6: Portugal | G6: Portugal | H6: Penafiel | J6: 1.8 | M6: Portugal | Q6: =IFERROR(VLOOKUP(portugal_clean[[#This Row],[Place of Birth]],region!A:B,2,FALSE),"") -> Porto
B7: Ricardo Campos | C7: Goalkeeper | D7: 31242 | E7: 38 | F7: Mozambique, Portugal | G7: Portugal | H7: Caldas da Rainha | J7: 1.88 | M7: Mozambique | N7: Portugal | Q7: =IFERROR(VLOOKUP(portugal_clean[[#This Row],[Place of Birth]],region!A:B,2,FALSE),"") -> Leiria
B8: Vasco Viana | C8: Goalkeeper | D8: 31157 | E8: 38 | F8: Portugal | G8: Portugal | H8: Felgueiras | J8: 1.96 | M8: Portugal | Q8: =IFERROR(VLOOKUP(portugal_clean[[#This Row],[Place of Birth]],region!A:B,2,FALSE),"") -> Porto
A9: 25.0 | B9: Pedro Fernandes | C9: Goalkeeper | D9: 31064 | E9: 39 | F9: Portugal | G9: Portugal | H9: Vila Real | J9: 1.85 | M9: Portugal | Q9: =IFERROR(VLOOKUP(portugal_clean[[#This Row],[Place of Birth]],region!A:B,2,FALSE),"") -> Vila Real
B10: Jorge Lemos | C10: Goalkeeper | D10: 31084 | E10: 39 | F10: Portugal | G10: Portugal | H10: Guimaraes | J10: 1.87 | M10: Portugal | Q10: =IFERROR(VLOOKUP(portugal_clean[[#This Row],[Place of Birth]],region!A:B,2,FALSE),"") -> Braga
B11: João Botelho | C11: Goalkeeper | D11: 31312 | E11: 38 | F11: Portugal | G11: Portugal | H11: Ponta Delgada | J11: 1.82 | M11: Portugal | Q11: =IFERROR(VLOOKUP(portugal_clean[[#This Row],[Place of Birth]],region!A:B,2,FALSE),"") -> Acores (Azores)
B12: Filipe Mendes | C12: Goalkeeper | D12: 31215 | E12: 38 | F12: Portugal | G12: Portugal | H12: Lisboa | J12: 1.93 | M12: Portugal | Q12: =IFERROR(VLOOKUP(portugal_clean[[#This Row],[Place of Birth]],region!A:B,2,FALSE),"") -> Lisboa
B13: André Queirós | C13: Goalkeeper | D13: 31253 | E13: 38 | F13: Portugal | G13: Portugal | H13: Aveiro | J13: 1.96 | M13: Portugal | Q13: =IFERROR(VLOOKUP(portugal_clean[[#This Row],[Place of Birth]],region!A:B,2,FALSE),"") -> Aveiro
B14: Nélson | C14: Goalkeeper | D14: 31110 | E14: 39 | F14: Portugal | G14: Portugal | H14: Figueira da Foz | J14: 1.88 | M14: Portugal | Q14: =IFERROR(VLOOKUP(portugal_clean[[#This Row],[Place of Birth]],region!A:B,2,FALSE),"") -> Coimbra
B15: Rui Rosindo | C15: Goalkeeper | D15: 31065 | E15: 39 | F15: Portugal | G15: Portugal | H15: Moura | M15: Portugal | Q15: =IFERROR(VLOOKUP(portugal_clean[[#This Row],[Place of Birth]],region!A:B,2,FALSE),"") -> Beja
B16: Nuno Laurentino | C16: Goalkeeper | D16: 31402 | E16: 38 | F16: Portugal | G16: Portugal | H16: Evora | J16: 1.85 | M16: Portugal | Q16: =IFERROR(VLOOKUP(portugal_clean[[#This Row],[Place of Birth]],region!A:B,2,FALSE),"") -> Evora
B17: Pedro Monteiro | C17: Goalkeeper | D17: 31342 | E17: 38 | F17: Portugal | G17: Portugal | H17: Oliveira de Azemeis | J17: 1.84 | M17: Portugal | Q17: =IFERROR(VLOOKUP(portugal_clean[[#This Row],[Place of Birth]],region!A:B,2,FALSE),"") -> Aveiro
B18: Ivo | C18: Goalkeeper | D18: 31187 | E18: 38 | F18: Portugal | G18: Portugal | H18: Gondomar | J18: 1.85 | M18: Portugal | Q18: =IFERROR(VLOOKUP(portugal_clean[[#This Row],[Place of Birth]],region!A:B,2,FALSE),"") -> Porto
B19: Hugo Magalhães | C19: Goalkeeper | D19: 31166 | E19: 38 | F19: Portugal | G19: Portugal | H19: Paredes | J19: 1.96 | M19: Portugal | Q19: =IFERROR(VLOOKUP(portugal_clean[[#This Row],[Place of Birth]],region!A:B,2,FALSE),"") -> Porto
B20: Rui Sacramento | C20: Goalkeeper | D20: 31078 | E20: 39 | F20: Portugal | G20: Portugal | H20: Matosinhos | J20: 1.84 | M20: Portugal | Q20: =IFERROR(VLOOKUP(portugal_clean[[#This Row],[Place of Birth]],region!A:B,2,FALSE),"") -> Porto
B21: Fonseca | C21: Goalkeeper | D21: 31052 | E21: 39 | F21: Portugal | G21: Portugal | H21: Porto | J21: 1.82 | M21: Portugal | Q21: =IFERROR(VLOOKUP(portugal_clean[[#This Row],[Place of Birth]],region!A:B,2,FALSE),"") -> Porto
B22: Pedro Cardoso | C22: Goalkeeper | D22: 31103 | E22: 39 | F22: Portugal | G22: Portugal | H22: Lisboa | J22: 1.81 | M22: Portugal | Q22: =IFERROR(VLOOKUP(portugal_clean[[#This Row],[Place of Birth]],region!A:B,2,FALSE),"") -> Lisboa
B23: Pedro Gomes | C23: Goalkeeper | D23: 31334 | E23: 38 | F23: Portugal | G23: Portugal | H23: Aveiro | J23: 1.84 | M23: Portugal | Q23: =IFERROR(VLOOKUP(portugal_clean[[#This Row],[Place of Birth]],region!A:B,2,FALSE),"") -> Aveiro
A24: 1.0 | B24: João Nuno | C24: Goalkeeper | D24: 31176 | E24: 38 | F24: Portugal | G24: Portugal | H24: Guimaraes | J24: 1.83 | M24: Portugal | Q24: =IFERROR(VLOOKUP(portugal_clean[[#This Row],[Place of Birth]],region!A:B,2,FALSE),"") -> Braga
B25: Gabriel | C25: Goalkeeper | D25: 31101 | E25: 39 | F25: Portugal | G25: Portugal | H25: Marco de Canaveses | M25: Portugal | Q25: =IFERROR(VLOOKUP(portugal_clean[[#This Row],[Place of Birth]],region!A:B,2,FALSE),"") -> Porto
A26: 33.0 | B26: Ricardo Batista | C26: Goalkeeper | D26: 31735 | E26: 37 | F26: Portugal, Angola | G26: Portugal | H26: Setubal | J26: 1.92 | M26: Portugal | N26: Angola | Q26: =IFERROR(VLOOKUP(portugal_clean[[#This Row],[Place of Birth]],region!A:B,2,FALSE),"") -> Setubal
A27: 31.0 | B27: Óscar | C27: Goalkeeper | D27: 31616 | E27: 37 | F27: Portugal | G27: Portugal | H27: Seia | J27: 1.9 | M27: Portugal | Q27: =IFERROR(VLOOKUP(portugal_clean[[#This Row],[Place of Birth]],region!A:B,2,FALSE),"") -> Guarda
A28: 28.0 | B28: Paulinho Baptista | C28: Goalkeeper | D28: 31436 | E28: 38 | F28: Portugal | G28: Portugal | H28: Ronfe | J28: 1.81 | M28: Portugal | Q28: =IFERROR(VLOOKUP(portugal_clean[[#This Row],[Place of Birth]],region!A:B,2,FALSE),"") -> Braga
A29: 99.0 | B29: Makê | C29: Goalkeeper | D29: 31657 | E29: 37 | F29: Portugal | G29: Portugal | H29: Marinha Grande | J29: 1.93 | M29: Portugal | Q29: =IFERROR(VLOOKUP(portugal_clean[[#This Row],[Place of Birth]],region!A:B,2,FALSE),"") -> Leiria
B30: João Nunes | C30: Goalkeeper | D30: 31553 | E30: 37 | F30: Portugal | G30: Portugal | H30: Povoa de Varzim | J30: 1.93 | M30: Portugal | Q30: =IFERROR(VLOOKUP(portugal_clean[[#This Row],[Place of Birth]],region!A:B,2,FALSE),"") -> Porto
B31: Paulo Cunha | C31: Goalkeeper | D31: 31462 | E31: 38 | F31: Portugal | G31: Portugal | H31: Vila Nova de Famalicao | J31: 1.91 | M31: Portugal | Q31: =IFERROR(VLOOKUP(portugal_clean[[#This Row],[Place of Birth]],region!A:B,2,FALSE),"") -> Braga
A32: 52.0 | B32: Márcio Guilherme | C32: Goalkeeper | D32: 31603 | E32: 37 | F32: Portugal | G32: Portugal | J32: 1.74 | M32: Portugal | Q32: =IFERROR(VLOOKUP(portugal_clean[[#This Row],[Place of Birth]],region!A:B,2,FALSE),"")
B33: Salgueiro | C33: Goalkeeper | D33: 31555 | E33: 37 | F33: Portugal | G33: Portugal | H33: Barcelos | J33: 1.87 | M33: Portugal | Q33: =IFERROR(VLOOKUP(portugal_clean[[#This Row],[Place of Birth]],region!A:B,2,FALSE),"") -> Braga
B34: João Barroca | C34: Goalkeeper | D34: 31622 | E34: 37 | F34: Portugal | G34: Portugal | H34: Mealhada | J34: 1.87 | M34: Portugal | Q34: =IFERROR(VLOOKUP(portugal_clean[[#This Row],[Place of Birth]],region!A:B,2,FALSE),"") -> Aveiro
B35: Castro | C35: Goalkeeper | D35: 31679 | E35: 37 | F35: Portugal | G35: Portugal | H35: Porto | J35: 1.9 | M35: Portugal | Q35: =IFERROR(VLOOKUP(portugal_clean[[#This Row],[Place of Birth]],region!A:B,2,FALSE),"") -> Porto
B36: Rui Nereu | C36: Goalkeeper | D36: 31447 | E36: 38 | F36: Portugal | G36: Portugal | H36: Torres Novas | J36: 1.83 | M36: Portugal | Q36: =IFERROR(VLOOKUP(portugal_clean[[#This Row],[Place of Birth]],region!A:B,2,FALSE),"") -> Santarem
B37: Fábio Monteiro | C37: Goalkeeper | D37: 31711 | E37: 37 | F37: Portugal | G37: Portugal | H37: Lissabon | J37: 1.88 | M37: Portugal | Q37: =IFERROR(VLOOKUP(portugal_clean[[#This Row],[Place of Birth]],region!A:B,2,FALSE),"") -> Lisboa
A38: 1.0 | B38: Hugo Marques | C38: Goalkeeper | D38: 31427 | E38: 38 | F38: Angola, Portugal | G38: Portugal | H38: Fao | J38: 1.9 | M38: Angola | N38: Portugal | Q38: =IFERROR(VLOOKUP(portugal_clean[[#This Row],[Place of Birth]],region!A:B,2,FALSE),"") -> Braga
A39: 14.0 | B39: José Borracha | C39: Goalkeeper | D39: 31429 | E39: 38 | F39: Portugal | G39: Portugal | H39: Cuba | J39: 1.84 | M39: Portugal | Q39: =IFERROR(VLOOKUP(portugal_clean[[#This Row],[Place of Birth]],region!A:B,2,FALSE),"") -> Beja
A40: 1.0 | B40: João Oliveira | C40: Goalkeeper | D40: 31440 | E40: 38 | F40: Portugal | G40: Portugal | H40: Ovar | M40: Portugal | Q40: =IFERROR(VLOOKUP(portugal_clean[[#This Row],[Place of Birth]],region!A:B,2,FALSE),"") -> Aveiro
...

Sheet region
A1: asciiname | B1: region
A2: Portuguese Republic
A3: Lisbon metropolitan area | B3: Lisboa
A4: Lisboa | B4: Lisboa
A5: Lissabon | B5: Lisboa
A6: Distrito de Lisboa | B6: Lisboa
A7: Distrito do Porto | B7: Porto
A8: Distrito de Braga | B8: Braga
A9: Distrito de Setubal | B9: Setubal
A10: Distrito de Aveiro | B10: Aveiro
A11: Lisbon | B11: Lisboa
A12: Lisbon | B12: Lisboa
A13: Distrito de Santarem | B13: Santarem
A14: Distrito de Leiria | B14: Leiria
... A6909: Sitio do Cano Amarelo | Yellow Pipe Place | B6909: Porto

Sheet TCD
A1: Nationality 2
A3: Étiquettes de lignes | B3: Nombre de Name
A4: Andorra | B4: 5
A5: Brazil | B5: 1
A6: China | B6: 1
A7: Germany | B7: 1
A8: Luxembourg | B8: 2
A9: Macao | B9: 7
A10: Norway | B10: 1
A11: Portugal | B11: 5960
A12: Serbia | B12: 2
A13: Total général | B13: 5980
